Workbook

Sheet Read me
A1: Four Realms: Gear Catalogue
A2: Built from your 185-row list of fictional weapons and artifacts.
A4: What's inside
A5: 101 weapons across 15 archetypes, 17 armours, 53 relics, 21 consumables and 13 other ideas (materials, hub features, boss mechanics).
A6: Names and effects are original, so the game ships no franchise names or designs. The Your rows column links each item back to your list, and the Your list sheet maps all 185 rows.
A7: 22 items are new designs that fill gaps in your list: starter weapons, bio-launchers, basic potions and armour.
A8: Boss names other than the Iron Warlord (Hollow King, Fallen Seraph, Hive Mother) are placeholders.
A10: How to tune
A11: Blue cells are inputs: base stats per archetype and multipliers per rarity on the Tuning sheet, plus each weapon's damage and speed tweaks on the Weapons sheet.
A12: Damage, Attacks/s, DPS, Range, armour stats and store prices are formulas, so they update when an input changes.
A13: Best for is the race whose affinity gives +10% damage with that archetype. Stats are level-1 values, before item level, forge upgrades and affixes.
A14: Stage is when the item ships, following the plan's roadmap.
A16: Counts by stage
A17: Stage | B17: New weapons | C17: Weapons in game | D17: Armour | E17: Relics | F17: Consumables
A18: 1 | B18: =COUNTIF(Weapons!$G:$G,A18) -> 12 | C18: =SUM($B$18:B18) -> 12 | D18: =COUNTIF(Armour!$D:$D,A18) -> 3 | E18: =COUNTIF(Relics!$D:$D,A18) -> 0 | F18: =COUNTIF(Consumables!$D:$D,A18) -> 3
A19: 2 | B19: =COUNTIF(Weapons!$G:$G,A19) -> 31 | C19: =SUM($B$18:B19) -> 43 | D19: =COUNTIF(Armour!$D:$D,A19) -> 5 | E19: =COUNTIF(Relics!$D:$D,A19) -> 21 | F19: =COUNTIF(Consumables!$D:$D,A19) -> 15
A20: 3 | B20: =COUNTIF(Weapons!$G:$G,A20) -> 0 | C20: =SUM($B$18:B20) -> 43 | D20: =COUNTIF(Armour!$D:$D,A20) -> 0 | E20: =COUNTIF(Relics!$D:$D,A20) -> 0 | F20: =COUNTIF(Consumables!$D:$D,A20) -> 0
A21: 4 | B21: =COUNTIF(Weapons!$G:$G,A21) -> 57 | C21: =SUM($B$18:B21) -> 100 | D21: =COUNTIF(Armour!$D:$D,A21) -> 7 | E21: =COUNTIF(Relics!$D:$D,A21) -> 26 | F21: =COUNTIF(Consumables!$D:$D,A21) -> 3
A22: 5 | B22: =COUNTIF(Weapons!$G:$G,A22) -> 0 | C22: =SUM($B$18:B22) -> 100 | D22: =COUNTIF(Armour!$D:$D,A22) -> 0 | E22: =COUNTIF(Relics!$D:$D,A22) -> 0 | F22: =COUNTIF(Consumables!$D:$D,A22) -> 0
A23: 6 | B23: =COUNTIF(Weapons!$G:$G,A23) -> 1 | C23: =SUM($B$18:B23) -> 101 | D23: =COUNTIF(Armour!$D:$D,A23) -> 2 | E23: =COUNTIF(Relics!$D:$D,A23) -> 6 | F23: =COUNTIF(Consumables!$D:$D,A23) -> 0
A24: Total | B24: =SUM(B18:B23) -> 101 | D24: =SUM(D18:D23) -> 17 | E24: =SUM(E18:E23) -> 53 | F24: =SUM(F18:F23) -> 21
A26: Rarity colours
A27: Common | B27: Uncommon | C27: Rare | D27: Epic | E27: Legendary | F27: Mythic

Sheet Weapons
A1: ID | B1: Name | C1: Archetype | D1: Best for | E1: Element | F1: Rarity | G1: Stage | H1: Signature effect | I1: How to get | J1: Set | K1: Damage tweak | L1: Speed tweak | M1: Damage | N1: Attacks/s | O1: DPS | P1: Range (px) | Q1: Your rows
A2: W001 | B2: Militia Blade | C2: Sword | D2: =INDEX(Tuning!$C$5:$C$19,MATCH($C2,Tuning!$A$5:$A$19,0)) -> Human | E2: Physical | F2: Common | G2: 1 | H2: Reliable 3-hit combo; the third hit staggers Minions. | I2: Starter (Human); drop: Act 1 | K2: 1 | L2: 1 | M2: =ROUND(INDEX(Tuning!$D$5:$D$19,MATCH($C2,Tuning!$A$5:$A$19,0))*INDEX(Tuning!$B$24:$B$29,MATCH($F2,Tuning!$A$24:$A$29,0))*K2,1) -> 14 | N2: =ROUND(INDEX(Tuning!$E$5:$E$19,MATCH($C2,Tuning!$A$5:$A$19,0))*L2,2) -> 1.6 | O2: =ROUND(M2*N2,1) -> 22.4 | P2: =INDEX(Tuning!$G$5:$G$19,MATCH($C2,Tuning!$A$5:$A$19,0)) -> 70 | Q2: New design
A3: W002 | B3: Shadow Ninjato Pair | C3: Sword | D3: =INDEX(Tuning!$C$5:$C$19,MATCH($C3,Tuning!$A$5:$A$19,0)) -> Human | E3: Physical | F3: Uncommon | G3: 1 | H3: Fast twin blades; hits from behind always crit. | I3: Drop: Act 1; store | K3: 1 | L3: 1 | M3: =ROUND(INDEX(Tuning!$D$5:$D$19,MATCH($C3,Tuning!$A$5:$A$19,0))*INDEX(Tuning!$B$24:$B$29,MATCH($F3,Tuning!$A$24:$A$29,0))*K3,1) -> 14.8 | N3: =ROUND(INDEX(Tuning!$E$5:$E$19,MATCH($C3,Tuning!$A$5:$A$19,0))*L3,2) -> 1.6 | O3: =ROUND(M3*N3,1) -> 23.7 | P3: =INDEX(Tuning!$G$5:$G$19,MATCH($C3,Tuning!$A$5:$A$19,0)) -> 70 | Q3: 181
A4: W003 | B4: Glimmer Shortsword | C4: Sword | D4: =INDEX(Tuning!$C$5:$C$19,MATCH($C4,Tuning!$A$5:$A$19,0)) -> Human | E4: Physical | F4: Rare | G4: 1 | H4: Glows brighter as your combo grows; at x5 combo it gains +20% crit chance. | I4: Drop: Act 1 Elites | K4: 1 | L4: 1 | M4: =ROUND(INDEX(Tuning!$D$5:$D$19,MATCH($C4,Tuning!$A$5:$A$19,0))*INDEX(Tuning!$B$24:$B$29,MATCH($F4,Tuning!$A$24:$A$29,0))*K4,1) -> 15.7 | N4: =ROUND(INDEX(Tuning!$E$5:$E$19,MATCH($C4,Tuning!$A$5:$A$19,0))*L4,2) -> 1.6 | O4: =ROUND(M4*N4,1) -> 25.1 | P4: =INDEX(Tuning!$G$5:$G$19,MATCH($C4,Tuning!$A$5:$A$19,0)) -> 70 | Q4: 88
A5: W004 | B5: Iron Cleaver | C5: Greatsword | D5: =INDEX(Tuning!$C$5:$C$19,MATCH($C5,Tuning!$A$5:$A$19,0)) -> Demon | E5: Physical | F5: Common | G5: 1 | H5: Wide arc; a charged slam knocks Minions down. | I5: Starter (Demon); drop: Act 1 | K5: 1 | L5: 1 | M5: =ROUND(INDEX(Tuning!$D$5:$D$19,MATCH($C5,Tuning!$A$5:$A$19,0))*INDEX(Tuning!$B$24:$B$29,MATCH($F5,Tuning!$A$24:$A$29,0))*K5,1) -> 26 | N5: =ROUND(INDEX(Tuning!$E$5:$E$19,MATCH($C5,Tuning!$A$5:$A$19,0))*L5,2) -> 0.8 | O5: =ROUND(M5*N5,1) -> 20.8 | P5: =INDEX(Tuning!$G$5:$G$19,MATCH($C5,Tuning!$A$5:$A$19,0)) -> 95 | Q5: New design
A6: W005 | B6: Squash Mallet | C6: Greatsword | D6: =INDEX(Tuning!$C$5:$C$19,MATCH($C6,Tuning!$A$5:$A$19,0)) -> Demon | E6: Physical | F6: Uncommon | G6: 1 | H6: Charged slam flattens enemies, stunning them for 1.5 s. | I6: Drop: Act 1; store | K6: 1 | L6: 1 | M6: =ROUND(INDEX(Tuning!$D$5:$D$19,MATCH($C6,Tuning!$A$5:$A$19,0))*INDEX(Tuning!$B$24:$B$29,MATCH($F6,Tuning!$A$24:$A$29,0))*K6,1) -> 27.6 | N6: =ROUND(INDEX(Tuning!$E$5:$E$19,MATCH($C6,Tuning!$A$5:$A$19,0))*L6,2) -> 0.8 | O6: =ROUND(M6*N6,1) -> 22.1 | P6: =INDEX(Tuning!$G$5:$G$19,MATCH($C6,Tuning!$A$5:$A$19,0)) -> 95 | Q6: 185
A7: W006 | B7: Gatebreaker Ram | C7: Greatsword | D7: =INDEX(Tuning!$C$5:$C$19,MATCH($C7,Tuning!$A$5:$A$19,0)) -> Demon | E7: Physical | F7: Rare | G7: 1 | H7: Charged slam breaks shields and armour; bosses take 30% more stagger. | I7: Boss: Iron Warlord (signature drop) | K7: 1 | L7: 1 | M7: =ROUND(INDEX(Tuning!$D$5:$D$19,MATCH($C7,Tuning!$A$5:$A$19,0))*INDEX(Tuning!$B$24:$B$29,MATCH($F7,Tuning!$A$24:$A$29,0))*K7,1) -> 29.1 | N7: =ROUND(INDEX(Tuning!$E$5:$E$19,MATCH($C7,Tuning!$A$5:$A$19,0))*L7,2) -> 0.8 | O7: =ROUND(M7*N7,1) -> 23.3 | P7: =INDEX(Tuning!$G$5:$G$19,MATCH($C7,Tuning!$A$5:$A$19,0)) -> 95 | Q7: 93
A8: W007 | B8: Ashwood Staff | C8: Staff | D8: =INDEX(Tuning!$C$5:$C$19,MATCH($C8,Tuning!$A$5:$A$19,0)) -> God | E8: Radiant | F8: Common | G8: 1 | H8: Homing bolts; every 5th bolt splits in two. | I8: Starter (God); drop: Act 1 | K8: 1 | L8: 1 | M8: =ROUND(INDEX(Tuning!$D$5:$D$19,MATCH($C8,Tuning!$A$5:$A$19,0))*INDEX(Tuning!$B$24:$B$29,MATCH($F8,Tuning!$A$24:$A$29,0))*K8,1) -> 11 | N8: =ROUND(INDEX(Tuning!$E$5:$E$19,MATCH($C8,Tuning!$A$5:$A$19,0))*L8,2) -> 1.8 | O8: =ROUND(M8*N8,1) -> 19.8 | P8: =INDEX(Tuning!$G$5:$G$19,MATCH($C8,Tuning!$A$5:$A$19,0)) -> 380 | Q8: New design
A9: W008 | B9: Horned Scepter | C9: Staff | D9: =INDEX(Tuning!$C$5:$C$19,MATCH($C9,Tuning!$A$5:$A$19,0)) -> God | E9: Hellfire | F9: Uncommon | G9: 1 | H9: Bolts curse enemies: cursed targets take 15% more damage for 4 s. | I9: Drop: Act 1; store | K9: 1 | L9: 1 | M9: =ROUND(INDEX(Tuning!$D$5:$D$19,MATCH($C9,Tuning!$A$5:$A$19,0))*INDEX(Tuning!$B$24:$B$29,MATCH($F9,Tuning!$A$24:$A$29,0))*K9,1) -> 11.7 | N9: =ROUND(INDEX(Tuning!$E$5:$E$19,MATCH($C9,Tuning!$A$5:$A$19,0))*L9,2) -> 1.8 | O9: =ROUND(M9*N9,1) -> 21.1 | P9: =INDEX(Tuning!$G$5:$G$19,MATCH($C9,Tuning!$A$5:$A$19,0)) -> 380 | Q9: 179
A10: W009 | B10: Gale Staff | C10: Staff | D10: =INDEX(Tuning!$C$5:$C$19,MATCH($C10,Tuning!$A$5:$A$19,0)) -> God | E10: Radiant | F10: Rare | G10: 1 | H10: Weapon skill releases an air burst that knocks back everything around you. | I10: Drop: Act 1 Elites | K10: 1 | L10: 1 | M10: =ROUND(INDEX(Tuning!$D$5:$D$19,MATCH($C10,Tuning!$A$5:$A$19,0))*INDEX(Tuning!$B$24:$B$29,MATCH($F10,Tuning!$A$24:$A$29,0))*K10,1) -> 12.3 | N10: =ROUND(INDEX(Tuning!$E$5:$E$19,MATCH($C10,Tuning!$A$5:$A$19,0))*L10,2) -> 1.8 | O10: =ROUND(M10*N10,1) -> 22.1 | P10: =INDEX(Tuning!$G$5:$G$19,MATCH($C10,Tuning!$A$5:$A$19,0)) -> 380 | Q10: 137
A11: W010 | B11: Scrap Torch | C11: Energy beam | D11: =INDEX(Tuning!$C$5:$C$19,MATCH($C11,Tuning!$A$5:$A$19,0)) -> Alien | E11: Physical | F11: Common | G11: 1 | H11: Short welding beam; damage rises 10% per second on one target (max +50%). | I11: Starter (Alien); drop: Act 1 | K11: 1 | L11: 1 | M11: =ROUND(INDEX(Tuning!$D$5:$D$19,MATCH($C11,Tuning!$A$5:$A$19,0))*INDEX(Tuning!$B$24:$B$29,MATCH($F11,Tuning!$A$24:$A$29,0))*K11,1) -> 4 | N11: =ROUND(INDEX(Tuning!$E$5:$E$19,MATCH($C11,Tuning!$A$5:$A$19,0))*L11,2) -> 10 | O11: =ROUND(M11*N11,1) -> 40 | P11: =INDEX(Tuning!$G$5:$G$19,MATCH($C11,Tuning!$A$5:$A$19,0)) -> 350 | Q11: New design
A12: W011 | B12: Torchline Cutter | C12: Energy beam | D12: =INDEX(Tuning!$C$5:$C$19,MATCH($C12,Tuning!$A$5:$A$19,0)) -> Alien | E12: Physical | F12: Uncommon | G12: 1 | H12: Narrow beam that ignores 25% of armour and cuts shields twice as fast. | I12: Drop: Act 1; store | K12: 1 | L12: 1 | M12: =ROUND(INDEX(Tuning!$D$5:$D$19,MATCH($C12,Tuning!$A$5:$A$19,0))*INDEX(Tuning!$B$24:$B$29,MATCH($F12,Tuning!$A$24:$A$29,0))*K12,1) -> 4.2 | N12: =ROUND(INDEX(Tuning!$E$5:$E$19,MATCH($C12,Tuning!$A$5:$A$19,0))*L12,2) -> 10 | O12: =ROUND(M12*N12,1) -> 42 | P12: =INDEX(Tuning!$G$5:$G$19,MATCH($C12,Tuning!$A$5:$A$19,0)) -> 350 | Q12: 6
A13: W012 | B13: Carnelian Prism | C13: Energy beam | D13: =INDEX(Tuning!$C$5:$C$19,MATCH($C13,Tuning!$A$5:$A$19,0)) -> Alien | E13: Hellfire | F13: Rare | G13: 1 | H13: The beam bounces off walls up to 2 times. | I13: Drop: Act 1 Elites | K13: 1 | L13: 1 | M13: =ROUND(INDEX(Tuning!$D$5:$D$19,MATCH($C13,Tuning!$A$5:$A$19,0))*INDEX(Tuning!$B$24:$B$29,MATCH($F13,Tuning!$A$24:$A$29,0))*K13,1) -> 4.5 | N13: =ROUND(INDEX(Tuning!$E$5:$E$19,MATCH($C13,Tuning!$A$5:$A$19,0))*L13,2) -> 10 | O13: =ROUND(M13*N13,1) -> 45 | P13: =INDEX(Tuning!$G$5:$G$19,MATCH($C13,Tuning!$A$5:$A$19,0)) -> 350 | Q13: 135
... A21: W020 | B21: Bloodforged Scythe | C21: Scythe | D21: =INDEX(Tuning!$C$5:$C$19,MATCH($C21,Tuning!$A$5:$A$19,0)) -> Demon | E21: Hellfire | F21: Legendary | G21: 2 | H21: Each hit costs 1 HP and deals 35% more damage; kills refund 5 HP. | I21: Boss: Hollow King (signature drop) | K21: 1 | L21: 1 | M21: =ROUND(INDEX(Tuning!$D$5:$D$19,MATCH($C21,Tuning!$A$5:$A$19,0))*INDEX(Tuning!$B$24:$B$29,MATCH($F21,Tuning!$A$24:$A$29,0))*K21,1) -> 23.4 | N21: =ROUND(INDEX(Tuning!$E$5:$E$19,MATCH($C21,Tuning!$A$5:$A$19,0))*L21,2) -> 1 | O21: =ROUND(M21*N21,1) -> 23.4 | P21: =INDEX(Tuning!$G$5:$G$19,MATCH($C21,Tuning!$A$5:$A$19,0)) -> 90 | Q21: 161
A22: W021 | B22: Godreaper Scythe | C22: Scythe | D22: =INDEX(Tuning!$C$5:$C$19,MATCH($C22,Tuning!$A$5:$A$19,0)) -> Demon | E22: Hellfire | F22: Mythic | G22: 2 | H22: +50% damage to Empyrean enemies; each kill raises a shadow beast that fights for 6 s. | I22: Arc finale: Act 2 | J22: Hollow Crown | K22: 1 | L22: 1 | M22: =ROUND(INDEX(Tuning!$D$5:$D$19,MATCH($C22,Tuning!$A$5:$A$19,0))*INDEX(Tuning!$B$24:$B$29,MATCH($F22,Tuning!$A$24:$A$29,0))*K22,1) -> 25.2 | N22: =ROUND(INDEX(Tuning!$E$5:$E$19,MATCH($C22,Tuning!$A$5:$A$19,0))*L22,2) -> 1 | O22: =ROUND(M22*N22,1) -> 25.2 | P22: =INDEX(Tuning!$G$5:$G$19,MATCH($C22,Tuning!$A$5:$A$19,0)) -> 90 | Q22: 46
A23: W022 | B23: Quickstrike Bo | C23: Spear | D23: =INDEX(Tuning!$C$5:$C$19,MATCH($C23,Tuning!$A$5:$A$19,0)) -> God | E23: Physical | F23: Common | G23: 2 | H23: Every 4th strike sweeps 360 degrees. | I23: Drop: Acts 1-2; store | K23: 1 | L23: 1 | M23: =ROUND(INDEX(Tuning!$D$5:$D$19,MATCH($C23,Tuning!$A$5:$A$19,0))*INDEX(Tuning!$B$24:$B$29,MATCH($F23,Tuning!$A$24:$A$29,0))*K23,1) -> 18 | N23: =ROUND(INDEX(Tuning!$E$5:$E$19,MATCH($C23,Tuning!$A$5:$A$19,0))*L23,2) -> 1.2 | O23: =ROUND(M23*N23,1) -> 21.6 | P23: =INDEX(Tuning!$G$5:$G$19,MATCH($C23,Tuning!$A$5:$A$19,0)) -> 130 | Q23: 166, 181
A24: W023 | B24: Hunter's Pike | C24: Spear | D24: =INDEX(Tuning!$C$5:$C$19,MATCH($C24,Tuning!$A$5:$A$19,0)) -> God | E24: Physical | F24: Uncommon | G24: 2 | H24: Hold attack to throw it; the weapon skill recalls it through enemies. | I24: Drop: Act 2 | K24: 1 | L24: 1 | M24: =ROUND(INDEX(Tuning!$D$5:$D$19,MATCH($C24,Tuning!$A$5:$A$19,0))*INDEX(Tuning!$B$24:$B$29,MATCH($F24,Tuning!$A$24:$A$29,0))*K24,1) -> 19.1 | N24: =ROUND(INDEX(Tuning!$E$5:$E$19,MATCH($C24,Tuning!$A$5:$A$19,0))*L24,2) -> 1.2 | O24: =ROUND(M24*N24,1) -> 22.9 | P24: =INDEX(Tuning!$G$5:$G$19,MATCH($C24,Tuning!$A$5:$A$19,0)) -> 130 | Q24: 124
A25: W024 | B25: Binding Lariat | C25: Spear | D25: =INDEX(Tuning!$C$5:$C$19,MATCH($C25,Tuning!$A$5:$A$19,0)) -> God | E25: Radiant | F25: Rare | G25: 2 | H25: A long lash that pulls the target to you; bound enemies can't use abilities for 3 s. | I25: Drop: Act 2 Elites | K25: 1 | L25: 1 | M25: =ROUND(INDEX(Tuning!$D$5:$D$19,MATCH($C25,Tuning!$A$5:$A$19,0))*INDEX(Tuning!$B$24:$B$29,MATCH($F25,Tuning!$A$24:$A$29,0))*K25,1) -> 20.2 | N25: =ROUND(INDEX(Tuning!$E$5:$E$19,MATCH($C25,Tuning!$A$5:$A$19,0))*L25,2) -> 1.2 | O25: =ROUND(M25*N25,1) -> 24.2 | P25: =INDEX(Tuning!$G$5:$G$19,MATCH($C25,Tuning!$A$5:$A$19,0)) -> 130 | Q25: 66
A26: W025 | B26: Tidecaller Trident | C26: Spear | D26: =INDEX(Tuning!$C$5:$C$19,MATCH($C26,Tuning!$A$5:$A$19,0)) -> God | E26: Physical | F26: Legendary | G26: 2 | H26: Weapon skill sends a wave that pushes all enemies back; in water it also calls two tide serpents for 10 s. | I26: Quest: The Drowned Gate (Act 2) | K26: 1 | L26: 1 | M26: =ROUND(INDEX(Tuning!$D$5:$D$19,MATCH($C26,Tuning!$A$5:$A$19,0))*INDEX(Tuning!$B$24:$B$29,MATCH($F26,Tuning!$A$24:$A$29,0))*K26,1) -> 23.4 | N26: =ROUND(INDEX(Tuning!$E$5:$E$19,MATCH($C26,Tuning!$A$5:$A$19,0))*L26,2) -> 1.2 | O26: =ROUND(M26*N26,1) -> 28.1 | P26: =INDEX(Tuning!$G$5:$G$19,MATCH($C26,Tuning!$A$5:$A$19,0)) -> 130 | Q26: 75, 184
A27: W026 | B27: Buzz Drone | C27: Drone | D27: =INDEX(Tuning!$C$5:$C$19,MATCH($C27,Tuning!$A$5:$A$19,0)) -> Alien | E27: Void | F27: Common | G27: 2 | H27: Fires small bolts at the nearest enemy. | I27: Store; drop: Act 2 | K27: 1 | L27: 1 | M27: =ROUND(INDEX(Tuning!$D$5:$D$19,MATCH($C27,Tuning!$A$5:$A$19,0))*INDEX(Tuning!$B$24:$B$29,MATCH($F27,Tuning!$A$24:$A$29,0))*K27,1) -> 7 | N27: =ROUND(INDEX(Tuning!$E$5:$E$19,MATCH($C27,Tuning!$A$5:$A$19,0))*L27,2) -> 2.5 | O27: =ROUND(M27*N27,1) -> 17.5 | P27: =INDEX(Tuning!$G$5:$G$19,MATCH($C27,Tuning!$A$5:$A$19,0)) -> 300 | Q27: New design
A28: W027 | B28: Kite Drone | C28: Drone | D28: =INDEX(Tuning!$C$5:$C$19,MATCH($C28,Tuning!$A$5:$A$19,0)) -> Alien | E28: Physical | F28: Uncommon | G28: 2 | H28: Marks the nearest Elite (it takes 15% more damage) and pecks it with lasers. | I28: Drop: Act 2 | K28: 1 | L28: 1 | M28: =ROUND(INDEX(Tuning!$D$5:$D$19,MATCH($C28,Tuning!$A$5:$A$19,0))*INDEX(Tuning!$B$24:$B$29,MATCH($F28,Tuning!$A$24:$A$29,0))*K28,1) -> 7.4 | N28: =ROUND(INDEX(Tuning!$E$5:$E$19,MATCH($C28,Tuning!$A$5:$A$19,0))*L28,2) -> 2.5 | O28: =ROUND(M28*N28,1) -> 18.5 | P28: =INDEX(Tuning!$G$5:$G$19,MATCH($C28,Tuning!$A$5:$A$19,0)) -> 300 | Q28: 19
A29: W028 | B29: Overzealous Drone | C29: Drone | D29: =INDEX(Tuning!$C$5:$C$19,MATCH($C29,Tuning!$A$5:$A$19,0)) -> Alien | E29: Void | F29: Rare | G29: 2 | H29: Fires 50% faster and also shoots breakable props, which can drop coins. | I29: Gold Rush | K29: 1 | L29: 1 | M29: =ROUND(INDEX(Tuning!$D$5:$D$19,MATCH($C29,Tuning!$A$5:$A$19,0))*INDEX(Tuning!$B$24:$B$29,MATCH($F29,Tuning!$A$24:$A$29,0))*K29,1) -> 7.8 | N29: =ROUND(INDEX(Tuning!$E$5:$E$19,MATCH($C29,Tuning!$A$5:$A$19,0))*L29,2) -> 2.5 | O29: =ROUND(M29*N29,1) -> 19.5 | P29: =INDEX(Tuning!$G$5:$G$19,MATCH($C29,Tuning!$A$5:$A$19,0)) -> 300 | Q29: 149
A30: W029 | B30: Kinblade Pair | C30: Sword | D30: =INDEX(Tuning!$C$5:$C$19,MATCH($C30,Tuning!$A$5:$A$19,0)) -> Human | E30: Physical | F30: Rare | G30: 2 | H30: Dual blades; every 4th hit is a cross-slash dealing double damage to Grunts and Brutes. | I30: Drop: Acts 1-2 Elites | K30: 1 | L30: 1 | M30: =ROUND(INDEX(Tuning!$D$5:$D$19,MATCH($C30,Tuning!$A$5:$A$19,0))*INDEX(Tuning!$B$24:$B$29,MATCH($F30,Tuning!$A$24:$A$29,0))*K30,1) -> 15.7 | N30: =ROUND(INDEX(Tuning!$E$5:$E$19,MATCH($C30,Tuning!$A$5:$A$19,0))*L30,2) -> 1.6 | O30: =ROUND(M30*N30,1) -> 25.1 | P30: =INDEX(Tuning!$G$5:$G$19,MATCH($C30,Tuning!$A$5:$A$19,0)) -> 70 | Q30: 89
A31: W030 | B31: Quillblade | C31: Sword | D31: =INDEX(Tuning!$C$5:$C$19,MATCH($C31,Tuning!$A$5:$A$19,0)) -> Human | E31: Physical | F31: Rare | G31: 2 | H31: As your sub weapon, it gives your main weapon +10% crit chance. | I31: Store | K31: 1 | L31: 1 | M31: =ROUND(INDEX(Tuning!$D$5:$D$19,MATCH($C31,Tuning!$A$5:$A$19,0))*INDEX(Tuning!$B$24:$B$29,MATCH($F31,Tuning!$A$24:$A$29,0))*K31,1) -> 15.7 | N31: =ROUND(INDEX(Tuning!$E$5:$E$19,MATCH($C31,Tuning!$A$5:$A$19,0))*L31,2) -> 1.6 | O31: =ROUND(M31*N31,1) -> 25.1 | P31: =INDEX(Tuning!$G$5:$G$19,MATCH($C31,Tuning!$A$5:$A$19,0)) -> 70 | Q31: 108
A32: W031 | B32: Twin Ember Sabres | C32: Sword | D32: =INDEX(Tuning!$C$5:$C$19,MATCH($C32,Tuning!$A$5:$A$19,0)) -> Human | E32: Hellfire | F32: Epic | G32: 2 | H32: Twin sabres; every 3rd strike sends out a wave of fire. | I32: Drop: Act 2 Champions | K32: 1 | L32: 1 | M32: =ROUND(INDEX(Tuning!$D$5:$D$19,MATCH($C32,Tuning!$A$5:$A$19,0))*INDEX(Tuning!$B$24:$B$29,MATCH($F32,Tuning!$A$24:$A$29,0))*K32,1) -> 16.8 | N32: =ROUND(INDEX(Tuning!$E$5:$E$19,MATCH($C32,Tuning!$A$5:$A$19,0))*L32,2) -> 1.6 | O32: =ROUND(M32*N32,1) -> 26.9 | P32: =INDEX(Tuning!$G$5:$G$19,MATCH($C32,Tuning!$A$5:$A$19,0)) -> 70 | Q32: 140
A33: W032 | B33: Rippleforge Longsword | C33: Sword | D33: =INDEX(Tuning!$C$5:$C$19,MATCH($C33,Tuning!$A$5:$A$19,0)) -> Human | E33: Physical | F33: Epic | G33: 2 | H33: Ignores 30% of armour and swings 20% faster. | I33: Store (rotating shelf) | K33: 1 | L33: 1.2 | M33: =ROUND(INDEX(Tuning!$D$5:$D$19,MATCH($C33,Tuning!$A$5:$A$19,0))*INDEX(Tuning!$B$24:$B$29,MATCH($F33,Tuning!$A$24:$A$29,0))*K33,1) -> 16.8 | N33: =ROUND(INDEX(Tuning!$E$5:$E$19,MATCH($C33,Tuning!$A$5:$A$19,0))*L33,2) -> 1.92 | O33: =ROUND(M33*N33,1) -> 32.3 | P33: =INDEX(Tuning!$G$5:$G$19,MATCH($C33,Tuning!$A$5:$A$19,0)) -> 70 | Q33: 104
A34: W033 | B34: Thornbound Blade | C34: Sword | D34: =INDEX(Tuning!$C$5:$C$19,MATCH($C34,Tuning!$A$5:$A$19,0)) -> Human | E34: Physical | F34: Epic | G34: 2 | H34: Cursed: once equipped it stays until the mission ends; every hit roots enemies for 0.3 s. | I34: Drop: Acts 1-2 Champions | K34: 1 | L34: 1 | M34: =ROUND(INDEX(Tuning!$D$5:$D$19,MATCH($C34,Tuning!$A$5:$A$19,0))*INDEX(Tuning!$B$24:$B$29,MATCH($F34,Tuning!$A$24:$A$29,0))*K34,1) -> 16.8 | N34: =ROUND(INDEX(Tuning!$E$5:$E$19,MATCH($C34,Tuning!$A$5:$A$19,0))*L34,2) -> 1.6 | O34: =ROUND(M34*N34,1) -> 26.9 | P34: =INDEX(Tuning!$G$5:$G$19,MATCH($C34,Tuning!$A$5:$A$19,0)) -> 70 | Q34: 160
... A87: W086 | B87: Ascendant Blade | C87: Sword | D87: =INDEX(Tuning!$C$5:$C$19,MATCH($C87,Tuning!$A$5:$A$19,0)) -> Human | E87: Radiant | F87: Legendary | G87: 4 | H87: Replaces your ultimate with a transformation: +40% to all stats for 12 s. | I87: Boss shop (Boss Tokens) | K87: 1 | L87: 1 | M87: =ROUND(INDEX(Tuning!$D$5:$D$19,MATCH($C87,Tuning!$A$5:$A$19,0))*INDEX(Tuning!$B$24:$B$29,MATCH($F87,Tuning!$A$24:$A$29,0))*K87,1) -> 18.2 | N87: =ROUND(INDEX(Tuning!$E$5:$E$19,MATCH($C87,Tuning!$A$5:$A$19,0))*L87,2) -> 1.6 | O87: =ROUND(M87*N87,1) -> 29.1 | P87: =INDEX(Tuning!$G$5:$G$19,MATCH($C87,Tuning!$A$5:$A$19,0)) -> 70 | Q87: 178
A88: W087 | B88: Sovereign Blade | C88: Sword | D88: =INDEX(Tuning!$C$5:$C$19,MATCH($C88,Tuning!$A$5:$A$19,0)) -> Human | E88: Radiant | F88: Mythic | G88: 4 | H88: +100% damage against shields; pairs with the Bloodless Scabbard. | I88: Arc finale: Act 3 | J88: Sovereign | K88: 1 | L88: 1 | M88: =ROUND(INDEX(Tuning!$D$5:$D$19,MATCH($C88,Tuning!$A$5:$A$19,0))*INDEX(Tuning!$B$24:$B$29,MATCH($F88,Tuning!$A$24:$A$29,0))*K88,1) -> 19.6 | N88: =ROUND(INDEX(Tuning!$E$5:$E$19,MATCH($C88,Tuning!$A$5:$A$19,0))*L88,2) -> 1.6 | O88: =ROUND(M88*N88,1) -> 31.4 | P88: =INDEX(Tuning!$G$5:$G$19,MATCH($C88,Tuning!$A$5:$A$19,0)) -> 70 | Q88: 107
A89: W088 | B89: Skyforge Maul | C89: Greatsword | D89: =INDEX(Tuning!$C$5:$C$19,MATCH($C89,Tuning!$A$5:$A$19,0)) -> Demon | E89: Radiant | F89: Legendary | G89: 4 | H89: Throw it with the weapon skill; it returns through enemies, and catching it charges your next swing with lightning. | I89: Drop: Act 3 Champions | K89: 1 | L89: 1 | M89: =ROUND(INDEX(Tuning!$D$5:$D$19,MATCH($C89,Tuning!$A$5:$A$19,0))*INDEX(Tuning!$B$24:$B$29,MATCH($F89,Tuning!$A$24:$A$29,0))*K89,1) -> 33.8 | N89: =ROUND(INDEX(Tuning!$E$5:$E$19,MATCH($C89,Tuning!$A$5:$A$19,0))*L89,2) -> 0.8 | O89: =ROUND(M89*N89,1) -> 27 | P89: =INDEX(Tuning!$G$5:$G$19,MATCH($C89,Tuning!$A$5:$A$19,0)) -> 95 | Q89: 9
A90: W089 | B90: Fourforce Greatblade | C90: Greatsword | D90: =INDEX(Tuning!$C$5:$C$19,MATCH($C90,Tuning!$A$5:$A$19,0)) -> Demon | E90: Rotates through all four | F90: Mythic | G90: 4 | H90: Its element rotates every 8 s; hits on a weakness deal +50%. | I90: Arc finale: Act 4 | J90: Fourforce | K90: 1 | L90: 1 | M90: =ROUND(INDEX(Tuning!$D$5:$D$19,MATCH($C90,Tuning!$A$5:$A$19,0))*INDEX(Tuning!$B$24:$B$29,MATCH($F90,Tuning!$A$24:$A$29,0))*K90,1) -> 36.4 | N90: =ROUND(INDEX(Tuning!$E$5:$E$19,MATCH($C90,Tuning!$A$5:$A$19,0))*L90,2) -> 0.8 | O90: =ROUND(M90*N90,1) -> 29.1 | P90: =INDEX(Tuning!$G$5:$G$19,MATCH($C90,Tuning!$A$5:$A$19,0)) -> 95 | Q90: 131
A91: W090 | B91: Dawnpiercer Spear | C91: Spear | D91: =INDEX(Tuning!$C$5:$C$19,MATCH($C91,Tuning!$A$5:$A$19,0)) -> God | E91: Radiant | F91: Legendary | G91: 4 | H91: The first thrust homes in on its target; hold the weapon skill to fire a radiant beam. | I91: Boss: Fallen Seraph (signature drop) | K91: 1 | L91: 1 | M91: =ROUND(INDEX(Tuning!$D$5:$D$19,MATCH($C91,Tuning!$A$5:$A$19,0))*INDEX(Tuning!$B$24:$B$29,MATCH($F91,Tuning!$A$24:$A$29,0))*K91,1) -> 23.4 | N91: =ROUND(INDEX(Tuning!$E$5:$E$19,MATCH($C91,Tuning!$A$5:$A$19,0))*L91,2) -> 1.2 | O91: =ROUND(M91*N91,1) -> 28.1 | P91: =INDEX(Tuning!$G$5:$G$19,MATCH($C91,Tuning!$A$5:$A$19,0)) -> 130 | Q91: 45
A92: W091 | B92: Atomsplit Glaive | C92: Spear | D92: =INDEX(Tuning!$C$5:$C$19,MATCH($C92,Tuning!$A$5:$A$19,0)) -> God | E92: Radiant | F92: Legendary | G92: 4 | H92: Critical hits ignore all defence and shields. | I92: Drop: Act 3 Champions | K92: 1 | L92: 1 | M92: =ROUND(INDEX(Tuning!$D$5:$D$19,MATCH($C92,Tuning!$A$5:$A$19,0))*INDEX(Tuning!$B$24:$B$29,MATCH($F92,Tuning!$A$24:$A$29,0))*K92,1) -> 23.4 | N92: =ROUND(INDEX(Tuning!$E$5:$E$19,MATCH($C92,Tuning!$A$5:$A$19,0))*L92,2) -> 1.2 | O92: =ROUND(M92*N92,1) -> 28.1 | P92: =INDEX(Tuning!$G$5:$G$19,MATCH($C92,Tuning!$A$5:$A$19,0)) -> 130 | Q92: 68
A93: W092 | B93: Banestone Pike | C93: Spear | D93: =INDEX(Tuning!$C$5:$C$19,MATCH($C93,Tuning!$A$5:$A$19,0)) -> God | E93: Void | F93: Epic | G93: 4 | H93: Each hit lowers the target's resistances by 5% (stacks 6); boss shields break 30% faster. | I93: Drop: Act 3 | K93: 1 | L93: 1 | M93: =ROUND(INDEX(Tuning!$D$5:$D$19,MATCH($C93,Tuning!$A$5:$A$19,0))*INDEX(Tuning!$B$24:$B$29,MATCH($F93,Tuning!$A$24:$A$29,0))*K93,1) -> 21.6 | N93: =ROUND(INDEX(Tuning!$E$5:$E$19,MATCH($C93,Tuning!$A$5:$A$19,0))*L93,2) -> 1.2 | O93: =ROUND(M93*N93,1) -> 25.9 | P93: =INDEX(Tuning!$G$5:$G$19,MATCH($C93,Tuning!$A$5:$A$19,0)) -> 130 | Q93: 55
A94: W093 | B94: Rallying Standard | C94: Spear | D94: =INDEX(Tuning!$C$5:$C$19,MATCH($C94,Tuning!$A$5:$A$19,0)) -> God | E94: Radiant | F94: Legendary | G94: 4 | H94: Once per room, plant it to raise a banner: +15% damage and 1% HP regen per second for 8 s. | I94: Quest: The Broken Banner (Act 3) | K94: 1 | L94: 1 | M94: =ROUND(INDEX(Tuning!$D$5:$D$19,MATCH($C94,Tuning!$A$5:$A$19,0))*INDEX(Tuning!$B$24:$B$29,MATCH($F94,Tuning!$A$24:$A$29,0))*K94,1) -> 23.4 | N94: =ROUND(INDEX(Tuning!$E$5:$E$19,MATCH($C94,Tuning!$A$5:$A$19,0))*L94,2) -> 1.2 | O94: =ROUND(M94*N94,1) -> 28.1 | P94: =INDEX(Tuning!$G$5:$G$19,MATCH($C94,Tuning!$A$5:$A$19,0)) -> 130 | Q94: 87
A95: W094 | B95: Farsight Staff | C95: Staff | D95: =INDEX(Tuning!$C$5:$C$19,MATCH($C95,Tuning!$A$5:$A$19,0)) -> God | E95: Radiant | F95: Epic | G95: 4 | H95: Weapon skill reveals hidden enemies and boss weak points for 5 s. | I95: Drop: Act 3 | K95: 1 | L95: 1 | M95: =ROUND(INDEX(Tuning!$D$5:$D$19,MATCH($C95,Tuning!$A$5:$A$19,0))*INDEX(Tuning!$B$24:$B$29,MATCH($F95,Tuning!$A$24:$A$29,0))*K95,1) -> 13.2 | N95: =ROUND(INDEX(Tuning!$E$5:$E$19,MATCH($C95,Tuning!$A$5:$A$19,0))*L95,2) -> 1.8 | O95: =ROUND(M95*N95,1) -> 23.8 | P95: =INDEX(Tuning!$G$5:$G$19,MATCH($C95,Tuning!$A$5:$A$19,0)) -> 380 | Q95: 180
A96: W095 | B96: Mirrorheart Wand | C96: Staff | D96: =INDEX(Tuning!$C$5:$C$19,MATCH($C96,Tuning!$A$5:$A$19,0)) -> God | E96: Matches your race | F96: Legendary | G96: 4 | H96: Changes with its wielder: rapid bolts (Human), fire bolts (Demon), healing orbs (God), void needles (Alien). | I96: Quest: The Four Mirrors (Act 3) | K96: 1 | L96: 1 | M96: =ROUND(INDEX(Tuning!$D$5:$D$19,MATCH($C96,Tuning!$A$5:$A$19,0))*INDEX(Tuning!$B$24:$B$29,MATCH($F96,Tuning!$A$24:$A$29,0))*K96,1) -> 14.3 | N96: =ROUND(INDEX(Tuning!$E$5:$E$19,MATCH($C96,Tuning!$A$5:$A$19,0))*L96,2) -> 1.8 | O96: =ROUND(M96*N96,1) -> 25.7 | P96: =INDEX(Tuning!$G$5:$G$19,MATCH($C96,Tuning!$A$5:$A$19,0)) -> 380 | Q96: 177
A97: W096 | B97: Solar Gaze | C97: Energy beam | D97: =INDEX(Tuning!$C$5:$C$19,MATCH($C97,Tuning!$A$5:$A$19,0)) -> Alien | E97: Radiant | F97: Legendary | G97: 4 | H97: Twin beams that burn; hold the weapon skill to narrow them for +60% crit chance. | I97: Drop: Act 3 Champions | K97: 1 | L97: 1 | M97: =ROUND(INDEX(Tuning!$D$5:$D$19,MATCH($C97,Tuning!$A$5:$A$19,0))*INDEX(Tuning!$B$24:$B$29,MATCH($F97,Tuning!$A$24:$A$29,0))*K97,1) -> 5.2 | N97: =ROUND(INDEX(Tuning!$E$5:$E$19,MATCH($C97,Tuning!$A$5:$A$19,0))*L97,2) -> 10 | O97: =ROUND(M97*N97,1) -> 52 | P97: =INDEX(Tuning!$G$5:$G$19,MATCH($C97,Tuning!$A$5:$A$19,0)) -> 350 | Q97: 59
A98: W097 | B98: Pip Cannon | C98: Pistol | D98: =INDEX(Tuning!$C$5:$C$19,MATCH($C98,Tuning!$A$5:$A$19,0)) -> Human | E98: Void | F98: Epic | G98: 4 | H98: Tiny pistol, huge blast: each shot deals 3x damage and knocks you back 3 m. | I98: Drop: Act 4 | K98: 3 | L98: 0.4 | M98: =ROUND(INDEX(Tuning!$D$5:$D$19,MATCH($C98,Tuning!$A$5:$A$19,0))*INDEX(Tuning!$B$24:$B$29,MATCH($F98,Tuning!$A$24:$A$29,0))*K98,1) -> 28.8 | N98: =ROUND(INDEX(Tuning!$E$5:$E$19,MATCH($C98,Tuning!$A$5:$A$19,0))*L98,2) -> 1.2 | O98: =ROUND(M98*N98,1) -> 34.6 | P98: =INDEX(Tuning!$G$5:$G$19,MATCH($C98,Tuning!$A$5:$A$19,0)) -> 420 | Q98: 126
A99: W098 | B99: Gatewright Pistol | C99: Pistol | D99: =INDEX(Tuning!$C$5:$C$19,MATCH($C99,Tuning!$A$5:$A$19,0)) -> Human | E99: Void | F99: Legendary | G99: 4 | H99: Alternate shots place an entry and an exit rift; shots fired into the entry come out of the exit. | I99: Drop: Act 4 Champions | K99: 1 | L99: 1 | M99: =ROUND(INDEX(Tuning!$D$5:$D$19,MATCH($C99,Tuning!$A$5:$A$19,0))*INDEX(Tuning!$B$24:$B$29,MATCH($F99,Tuning!$A$24:$A$29,0))*K99,1) -> 10.4 | N99: =ROUND(INDEX(Tuning!$E$5:$E$19,MATCH($C99,Tuning!$A$5:$A$19,0))*L99,2) -> 3 | O99: =ROUND(M99*N99,1) -> 31.2 | P99: =INDEX(Tuning!$G$5:$G$19,MATCH($C99,Tuning!$A$5:$A$19,0)) -> 420 | Q99: 145
...

Sheet Armour
A1: ID | B1: Name | C1: Rarity | D1: Stage | E1: Defence | F1: Bonus HP | G1: Effect | H1: How to get | I1: Set | J1: Your rows
A2: A01 | B2: Padded Jerkin | C2: Common | D2: 1 | E2: =INDEX(Tuning!$D$24:$D$29,MATCH($C2,Tuning!$A$24:$A$29,0)) -> 3 | F2: =INDEX(Tuning!$E$24:$E$29,MATCH($C2,Tuning!$A$24:$A$29,0)) -> 10 | G2: Cheap, light starter armour. | H2: Starter; store | J2: New design
A3: A02 | B3: Chain Hauberk | C3: Uncommon | D3: 1 | E3: =INDEX(Tuning!$D$24:$D$29,MATCH($C3,Tuning!$A$24:$A$29,0)) -> 4 | F3: =INDEX(Tuning!$E$24:$E$29,MATCH($C3,Tuning!$A$24:$A$29,0)) -> 15 | G3: Blocks 10% of melee damage. | H3: Drop: Act 1; store | J3: New design
A4: A03 | B4: Riftguard Vest | C4: Rare | D4: 1 | E4: =INDEX(Tuning!$D$24:$D$29,MATCH($C4,Tuning!$A$24:$A$29,0)) -> 5 | F4: =INDEX(Tuning!$E$24:$E$29,MATCH($C4,Tuning!$A$24:$A$29,0)) -> 20 | G4: After you touch a Rift Shrine, take 20% less damage for 30 s. | H4: Drop: Act 1 Elites | J4: New design
A5: A04 | B5: Moonsilver Mail | C5: Epic | D5: 2 | E5: =INDEX(Tuning!$D$24:$D$29,MATCH($C5,Tuning!$A$24:$A$29,0)) -> 6 | F5: =INDEX(Tuning!$E$24:$E$29,MATCH($C5,Tuning!$A$24:$A$29,0)) -> 25 | G5: +10% move speed; the perfect-dodge window lasts 0.05 s longer. | H5: Drop: Act 2 Champions | J5: 90
A6: A05 | B6: Kinetic Weave | C6: Legendary | D6: 2 | E6: =INDEX(Tuning!$D$24:$D$29,MATCH($C6,Tuning!$A$24:$A$29,0)) -> 8 | F6: =INDEX(Tuning!$E$24:$E$29,MATCH($C6,Tuning!$A$24:$A$29,0)) -> 35 | G6: Stores 30% of damage taken; your next melee hit releases it as a pulse (up to 60). | H6: Drop: Act 2 Champions | J6: 32
A7: A06 | B7: Siegeframe Plate | C7: Epic | D7: 2 | E7: =INDEX(Tuning!$D$24:$D$29,MATCH($C7,Tuning!$A$24:$A$29,0)) -> 6 | F7: =INDEX(Tuning!$E$24:$E$29,MATCH($C7,Tuning!$A$24:$A$29,0)) -> 25 | G7: +40% HP and -15% move speed; your melee hits stagger Brutes. | H7: Store (rotating shelf) | J7: 8
A8: A07 | B8: Projectile Ward Harness | C8: Epic | D8: 2 | E8: =INDEX(Tuning!$D$24:$D$29,MATCH($C8,Tuning!$A$24:$A$29,0)) -> 6 | F8: =INDEX(Tuning!$E$24:$E$29,MATCH($C8,Tuning!$A$24:$A$29,0)) -> 25 | G8: -50% damage from projectiles, +20% damage taken from melee. | H8: Drop: Act 2 | J8: 120
A9: A08 | B9: Lifeburn Exoframe | C9: Mythic | D9: 2 | E9: =INDEX(Tuning!$D$24:$D$29,MATCH($C9,Tuning!$A$24:$A$29,0)) -> 10 | F9: =INDEX(Tuning!$E$24:$E$29,MATCH($C9,Tuning!$A$24:$A$29,0)) -> 45 | G9: Doubles damage and resource gain, but drains 1% HP per second in combat. | H9: Arc finale: Act 2 | I9: Hollow Crown | J9: 154
A10: A09 | B10: Living Mantle | C10: Legendary | D10: 4 | E10: =INDEX(Tuning!$D$24:$D$29,MATCH($C10,Tuning!$A$24:$A$29,0)) -> 8 | F10: =INDEX(Tuning!$E$24:$E$29,MATCH($C10,Tuning!$A$24:$A$29,0)) -> 35 | G10: A living cloak: blocks one projectile every 5 s and stuns an attacker for 1 s when you're hit. | H10: Drop: Act 3 Champions | J10: 27
A11: A10 | B11: Mirrorplate | C11: Epic | D11: 4 | E11: =INDEX(Tuning!$D$24:$D$29,MATCH($C11,Tuning!$A$24:$A$29,0)) -> 6 | F11: =INDEX(Tuning!$E$24:$E$29,MATCH($C11,Tuning!$A$24:$A$29,0)) -> 25 | G11: Every 6th projectile that hits you is reflected at full damage. | H11: Drop: Act 3 | J11: 69
A12: A11 | B12: Starsteel Plate | C12: Epic | D12: 4 | E12: =INDEX(Tuning!$D$24:$D$29,MATCH($C12,Tuning!$A$24:$A$29,0)) -> 6 | F12: =INDEX(Tuning!$E$24:$E$29,MATCH($C12,Tuning!$A$24:$A$29,0)) -> 25 | G12: -30% damage from projectiles and beams; immune to burning. | H12: Drop: Act 4 | J12: 112
A13: A12 | B13: Starborn Weave | C13: Epic | D13: 4 | E13: =INDEX(Tuning!$D$24:$D$29,MATCH($C13,Tuning!$A$24:$A$29,0)) -> 6 | F13: =INDEX(Tuning!$E$24:$E$29,MATCH($C13,Tuning!$A$24:$A$29,0)) -> 25 | G13: Regenerates 1% HP per second while your resource bar is above half. | H13: Drop: Act 4 | J13: 58
A14: A13 | B14: Nightveil Cloak | C14: Legendary | D14: 4 | E14: =INDEX(Tuning!$D$24:$D$29,MATCH($C14,Tuning!$A$24:$A$29,0)) -> 8 | F14: =INDEX(Tuning!$E$24:$E$29,MATCH($C14,Tuning!$A$24:$A$29,0)) -> 35 | G14: Stand still for 1 s to turn invisible; your first hit from invisibility always crits. | H14: Drop: Act 3 Champions | J14: 96
A15: A14 | B15: Quicksilver Plate | C15: Legendary | D15: 4 | E15: =INDEX(Tuning!$D$24:$D$29,MATCH($C15,Tuning!$A$24:$A$29,0)) -> 8 | F15: =INDEX(Tuning!$E$24:$E$29,MATCH($C15,Tuning!$A$24:$A$29,0)) -> 35 | G15: Liquid-metal armour that blocks the first hit every 8 s, then reforms. | H15: Drop: Act 4 Champions | J15: 2
A16: A15 | B16: Living Carapace | C16: Legendary | D16: 4 | E16: =INDEX(Tuning!$D$24:$D$29,MATCH($C16,Tuning!$A$24:$A$29,0)) -> 8 | F16: =INDEX(Tuning!$E$24:$E$29,MATCH($C16,Tuning!$A$24:$A$29,0)) -> 35 | G16: +20% damage to whichever of melee, shooting or dashing you used most in the last 10 s. | H16: Drop: Act 4 Champions | J16: 82
A17: A16 | B17: Overdrive Exosuit | C17: Mythic | D17: 6 | E17: =INDEX(Tuning!$D$24:$D$29,MATCH($C17,Tuning!$A$24:$A$29,0)) -> 10 | F17: =INDEX(Tuning!$E$24:$E$29,MATCH($C17,Tuning!$A$24:$A$29,0)) -> 45 | G17: +50% damage and +30% HP, but drains 2 resource per second in combat; at zero you move 50% slower for 5 s. | H17: Rift Lord event | J17: 57
A18: A17 | B18: Seer's Regalia | C18: Mythic | D18: 6 | E18: =INDEX(Tuning!$D$24:$D$29,MATCH($C18,Tuning!$A$24:$A$29,0)) -> 10 | F18: =INDEX(Tuning!$E$24:$E$29,MATCH($C18,Tuning!$A$24:$A$29,0)) -> 45 | G18: +40% Arcane and you float over ground hazards, but you can't use consumables while wearing it. | H18: Rift Lord event | J18: 81

Sheet Relics
A1: ID | B1: Name | C1: Rarity | D1: Stage | E1: Effect | F1: How to get | G1: Set | H1: Your rows
A2: R01 | B2: Warden's Badge | C2: Uncommon | D2: 2 | E2: +10% XP and coin find; your coin Echo shows on the minimap. | F2: Drop: Acts 1-2; store | H2: 133
A3: R02 | B3: Field Belt | C3: Uncommon | D3: 2 | E3: +1 consumable slot; one consumable charge refills each mission. | F3: Store | H3: 52
A4: R03 | B4: Shrine Lantern | C4: Uncommon | D4: 2 | E4: Each Rift Shrine you touch stores a charge (max 3); spend one to refill your resource bar. | F4: Store | H4: 73
A5: R04 | B5: Hazard Ward | C5: Uncommon | D5: 2 | E5: -50% damage from environmental hazards and ground zones. | F5: Store | H5: 74
A6: R05 | B6: Clingstep Soles | C6: Uncommon | D6: 2 | E6: Immune to knockback and ice; dashing off a wall gives a free second dash. | F6: Drop: Act 2 | H6: 24
A7: R06 | B7: Medic Beads | C7: Rare | D7: 2 | E7: Potions heal 30% more and cleanse burn and poison. | F7: Store | H7: 34
A8: R07 | B8: Quickload Bandolier | C8: Rare | D8: 2 | E8: Active-reload sweet spot is 50% wider; reloads are 30% faster. | F8: Store | H8: 21
A9: R08 | B9: Analyst Lens | C9: Rare | D9: 2 | E9: Shows enemy HP numbers and weak elements; +10% crit on a target after aiming at it for 2 s. | F9: Store | H9: 7
A10: R09 | B10: Dread Sense | C10: Rare | D10: 2 | E10: Enemy telegraphs appear 0.2 s earlier. | F10: Drop: Act 2 Elites | H10: 23
A11: R10 | B11: Lodestone Bracer | C11: Rare | D11: 2 | E11: Thrown weapons return 40% faster and drag pickups along their path. | F11: Drop: Act 2 | H11: 16
A12: R11 | B12: Tracker Lens | C12: Rare | D12: 2 | E12: Shows enemies through walls and hidden caches within 20 m. | F12: Drop: Act 2 | H12: 54
A13: R12 | B13: Hookline Launcher | C13: Rare | D13: 2 | E13: Dash at a target to grapple to it; small enemies are pulled to you instead. | F13: Drop: Act 2 Elites | H13: 50, 143
... A25: R24 | B25: Farseer Orb | C25: Rare | D25: 4 | E25: Preview the next room's enemies before you open its door. | F25: Drop: Act 3 | H25: 92
A26: R25 | B26: Ring of Kindling | C26: Rare | D26: 4 | E26: +20% resource regen. Wearing any 2 Triune rings adds +10% to all stats. | F26: Drop: Act 3 | G26: Triune Rings | H26: 84
A27: R26 | B27: Ring of Stillwater | C27: Rare | D27: 4 | E27: Buffs and consumables last 30% longer. Triune set. | F27: Drop: Act 3 | G27: Triune Rings | H27: 85
A28: R27 | B28: Ring of Highwind | C28: Rare | D28: 4 | E28: Heal 1% HP per second out of combat and 0.3% in combat. Triune set. | F28: Drop: Act 3 | G28: Triune Rings | H28: 86
A29: R28 | B29: Kestrel Wings | C29: Epic | D29: 4 | E29: Dash distance +60%; dashing over gaps and ground hazards is safe. | F29: Drop: Act 3 | H29: 18, 51
A30: R29 | B30: Stormcaller Torc | C30: Epic | D30: 4 | E30: Every 5th hit calls down a radiant lightning bolt on the target. | F30: Drop: Act 3 | H30: 13
A31: R30 | B31: Twinring | C31: Epic | D31: 4 | E31: Your dash leaves a rift; dash again within 5 s to return to it. | F31: Drop: Act 3 | H31: 28
A32: R31 | B32: Dawnlight Vial | C32: Epic | D32: 4 | E32: Raise it with Interact to blind and repel nearby enemies for 3 s (30 s cooldown). | F32: Drop: Act 3 | H32: 91
A33: R32 | B33: Throat of Command | C33: Epic | D33: 4 | E33: Your parries also stun Minions and Veterans within 4 m for 1 s. | F33: Drop: Act 3 | H33: 122
A34: R33 | B34: Astral Double | C34: Epic | D34: 4 | E34: Once per room, project a shadow double that taunts enemies for 4 s. | F34: Drop: Act 3 | H34: 169
A35: R34 | B35: Velocity Aura | C35: Epic | D35: 4 | E35: +15% move speed; after 2 s at full speed, your dash damages everything it passes. | F35: Drop: Act 4 | H35: 77
A36: R35 | B36: Stiltlimb Rig | C36: Epic | D36: 4 | E36: A mechanical limb strikes any enemy within melee range, once per second. | F36: Drop: Act 4 | H36: 22
A37: R36 | B37: Kinetic Aura | C37: Epic | D37: 4 | E37: Pick up stunned enemies with Interact and throw them for heavy damage. | F37: Drop: Act 4 Champions | H37: 62, 118
A38: R37 | B38: Wayfinder Cube | C38: Epic | D38: 4 | E38: Heals are 25% stronger; fast-travel between discovered shrines in the act. | F38: Drop: Act 4 | H38: 79
A39: R38 | B39: Echoing Charm | C39: Epic | D39: 4 | E39: Abilities have a 15% chance to cast twice. | F39: Drop: Act 4 | H39: 134
A40: R39 | B40: Implant Kit | C40: Epic | D40: 4 | E40: Your dash fires 4 darts, and you can't be slowed. | F40: Drop: Act 4 | H40: 147
... A46: R45 | B46: Haven Bubble | C46: Legendary | D46: 4 | E46: Hold Parry for 1 s to raise a bubble that blocks all damage for 2 s (30 s cooldown). | F46: Boss shop (Boss Tokens) | H46: 174
A47: R46 | B47: Bloodless Scabbard | C47: Mythic | D47: 4 | E47: Immune to damage over time. With the Sovereign Blade: +25% damage. | F47: Arc finale: Act 3 | G47: Sovereign | H47: 107
A48: R47 | B48: Skinthief Core | C48: Mythic | D48: 4 | E48: Absorb the form of a Champion you defeat; once per room, become it for 10 s. | F48: Arc finale: Act 4 | G48: Fourforce | H48: 127, 130
A49: R48 | B49: Turnback Hourglass | C49: Mythic | D49: 6 | E49: Once per room, rewind 3 s: you return to where you were, with the HP you had. | F49: Rift Lord event | H49: 26, 42, 99
A50: R49 | B50: Hollow Core | C50: Mythic | D50: 6 | E50: Holds up to four Realm Shards and grants all their powers at once. | F50: Story finale | G50: Realm Shards | H50: 37, 129, 155
A51: R50 | B51: Ironheart Shard | C51: Mythic | D51: 6 | E51: Earth shard: +25% damage; every 10th hit releases a shockwave. | F51: Story: Realm Shard quest | G51: Realm Shards | H51: 41
A52: R51 | B52: Ember Shard | C52: Mythic | D52: 6 | E52: Abyss shard: kills heal 2% HP; slain Elites rise as spirit allies for 15 s. | F52: Story: Realm Shard quest | G52: Realm Shards | H52: 43
A53: R52 | B53: Dawn Shard | C53: Mythic | D53: 6 | E53: Empyrean shard: an Elite you parry fights for you for 10 s. | F53: Story: Realm Shard quest | G53: Realm Shards | H53: 39
A54: R53 | B54: Null Shard | C54: Mythic | D54: 6 | E54: Void shard: your dash blinks through walls; once per room, every enemy projectile on screen turns into coins. | F54: Story: Realm Shard quest | G54: Realm Shards | H54: 38, 40

Sheet Consumables
A1: ID | B1: Name | C1: Rarity | D1: Stage | E1: Effect | F1: How to get | G1: Store price (coins) | H1: Your rows
A2: C01 | B2: Minor Healing Draught | C2: Common | D2: 1 | E2: Heals 30% HP over 2 s. | F2: Store | G2: =IF(ISNUMBER(SEARCH("Store",F2)),INDEX(Tuning!$F$24:$F$29,MATCH($C2,Tuning!$A$24:$A$29,0)),"") -> 25 | H2: New design
A3: C02 | B3: Resource Tonic | C3: Common | D3: 1 | E3: Refills 50% of your resource bar. | F3: Store | G3: =IF(ISNUMBER(SEARCH("Store",F3)),INDEX(Tuning!$F$24:$F$29,MATCH($C3,Tuning!$A$24:$A$29,0)),"") -> 25 | H3: New design
A4: C03 | B4: Greater Healing Draught | C4: Uncommon | D4: 1 | E4: Heals 60% HP instantly. | F4: Store | G4: =IF(ISNUMBER(SEARCH("Store",F4)),INDEX(Tuning!$F$24:$F$29,MATCH($C4,Tuning!$A$24:$A$29,0)),"") -> 60 | H4: New design
A5: C04 | B5: Bridge Sigil | C5: Uncommon | D5: 2 | E5: Return to the hub, then come back to the same shrine. | F5: Store | G5: =IF(ISNUMBER(SEARCH("Store",F5)),INDEX(Tuning!$F$24:$F$29,MATCH($C5,Tuning!$A$24:$A$29,0)),"") -> 60 | H5: 12
A6: C05 | B6: Moonroot Tonic | C6: Uncommon | D6: 2 | E6: For 60 s, hidden enemies show on the minimap and you move 15% faster. | F6: Store | G6: =IF(ISNUMBER(SEARCH("Store",F6)),INDEX(Tuning!$F$24:$F$29,MATCH($C6,Tuning!$A$24:$A$29,0)),"") -> 60 | H6: 35
A7: C06 | B7: Override Key | C7: Uncommon | D7: 2 | E7: Hacks an enemy turret or drone to fight for you for 15 s, or opens a locked vault. | F7: Drop: Acts 1-4 | G7: =IF(ISNUMBER(SEARCH("Store",F7)),INDEX(Tuning!$F$24:$F$29,MATCH($C7,Tuning!$A$24:$A$29,0)),"") | H7: 53
A8: C07 | B8: Seeker's Map | C8: Uncommon | D8: 2 | E8: For one mission, every enemy and every Mimic chest shows on the minimap. | F8: Store | G8: =IF(ISNUMBER(SEARCH("Store",F8)),INDEX(Tuning!$F$24:$F$29,MATCH($C8,Tuning!$A$24:$A$29,0)),"") -> 60 | H8: 100
A9: C08 | B9: Shadowcap Lantern | C9: Uncommon | D9: 2 | E9: Darkens the room for 3 s; ranged enemies can't target you. | F9: Store | G9: =IF(ISNUMBER(SEARCH("Store",F9)),INDEX(Tuning!$F$24:$F$29,MATCH($C9,Tuning!$A$24:$A$29,0)),"") -> 60 | H9: 102
A10: C09 | B10: Viper Needle | C10: Uncommon | D10: 2 | E10: Your next hit poisons for 10% of the target's max HP over 6 s. | F10: Store | G10: =IF(ISNUMBER(SEARCH("Store",F10)),INDEX(Tuning!$F$24:$F$29,MATCH($C10,Tuning!$A$24:$A$29,0)),"") -> 60 | H10: 121
A11: C10 | B11: Jury-Rigged Bomb | C11: Uncommon | D11: 2 | E11: A huge blast, but 1 in 5 fizzle. | F11: Store | G11: =IF(ISNUMBER(SEARCH("Store",F11)),INDEX(Tuning!$F$24:$F$29,MATCH($C11,Tuning!$A$24:$A$29,0)),"") -> 60 | H11: 148
A12: C11 | B12: Prime Serum | C12: Rare | D12: 2 | E12: For 30 s: +20% damage, +20% move speed and steady HP regen. | F12: Store | G12: =IF(ISNUMBER(SEARCH("Store",F12)),INDEX(Tuning!$F$24:$F$29,MATCH($C12,Tuning!$A$24:$A$29,0)),"") -> 150 | H12: 17
A13: C12 | B13: Chainward Talisman | C13: Rare | D13: 2 | E13: Binds the target in chains for 3 s (1 s on bosses). | F13: Store | G13: =IF(ISNUMBER(SEARCH("Store",F13)),INDEX(Tuning!$F$24:$F$29,MATCH($C13,Tuning!$A$24:$A$29,0)),"") -> 150 | H13: 30
... A22: C21 | B22: Pocket Hole | C22: Epic | D22: 4 | E22: Throw it on the floor; Minions that walk in drop out of the fight. | F22: Gold Rush | G22: =IF(ISNUMBER(SEARCH("Store",F22)),INDEX(Tuning!$F$24:$F$29,MATCH($C22,Tuning!$A$24:$A$29,0)),"") | H22: 185

Sheet Other ideas
A1: ID | B1: Name | C1: Type | D1: Stage | E1: How it's used | F1: Your rows
A2: X01 | B2: Rift Recall | C2: Lore for revives | D2: 1 | E2: In-world reason for unlimited revives: shrines pull your essence back. | F2: 150
A3: X02 | B3: Obsidian Edge | C3: Forge material | D3: 2 | E3: Weapons upgraded with it deal +25% to spirits and undead. | F3: 105
A4: X03 | B4: Phylactery | C4: Boss mechanic | D4: 2 | E4: The Hollow King can't die until 3 soul jars in the arena are broken. | F4: 103
A5: X04 | B5: Shapeshifter boss | C5: Boss design | D5: 2 | E5: The Hollow King switches beast forms and regenerates unless hit with Radiant. | F5: 159
A6: X05 | B6: Memory Pool | C6: Hub feature | D6: 3 | E6: Rewatch your best runs and competition replays. | F6: 101
A7: X06 | B7: Starfall Ore | C7: Forge material | D7: 4 | E7: Found in Act 4; the forge turns it into the Meteor Jian. | F7: 138
A8: X07 | B8: Starcore Key | C8: Key item | D8: 4 | E8: Unlocks the hub's Sanctum vault; only level 30+ characters can carry it. | F8: 64
A9: X08 | B9: Rewind Altar | C9: Hub feature | D9: 4 | E9: Rematch any defeated boss for its loot table. | F9: 78
A10: X09 | B10: Field Journals | C10: Codex system | D10: 4 | E10: Three journals hidden in levels unlock the bestiary and lore codex. | F10: 171
A11: X10 | B11: Null Theorem | C11: Boss mechanic | D11: 6 | E11: A Rift Lord attack that reverses your controls for 3 s, telegraphed by a purple glyph. | F11: 80
A12: X11 | B12: Hero's Codex | C12: Key item | D12: 6 | E12: Socket boss sigils into it to open the hidden Time Vault. | F12: 164
A13: X12 | B13: Realm Shard quest | C13: Story | D13: 6 | E13: The four shards are pieces of the World Core; gathering them unlocks the endings. | F13: 129
A14: X13 | B14: Vehicles | C14: Not used | E14: No vehicle system is planned; a candidate for a later mount or vehicle feature. | F14: 56

Sheet Tuning
A1: Tuning
A2: Blue cells are inputs. Weapon, armour and price numbers on the other sheets are formulas that read these two tables. Values are starting points from the plan, meant to be tuned with playtest data.
A4: Archetype | B4: Plays as | C4: Best for | D4: Damage per hit | E4: Attacks/s | F4: Base DPS | G4: Range (px) | H4: First stage | I4: Named weapons
A5: Sword | B5: 3-hit combo arc | C5: Human | D5: 14 | E5: 1.6 | F5: =ROUND(D5*E5,1) -> 22.4 | G5: 70 | H5: 1 | I5: =COUNTIF(Weapons!$C:$C,A5) -> 18
A6: Greatsword | B6: Slow wide arc, charged slam | C6: Demon | D6: 26 | E6: 0.8 | F6: =ROUND(D6*E6,1) -> 20.8 | G6: 95 | H6: 1 | I6: =COUNTIF(Weapons!$C:$C,A6) -> 9
A7: Staff | B7: Homing bolts | C7: God | D7: 11 | E7: 1.8 | F7: =ROUND(D7*E7,1) -> 19.8 | G7: 380 | H7: 1 | I7: =COUNTIF(Weapons!$C:$C,A7) -> 7
A8: Energy beam | B8: Continuous beam that builds heat | C8: Alien | D8: 4 | E8: 10 | F8: =ROUND(D8*E8,1) -> 40 | G8: 350 | H8: 1 | I8: =COUNTIF(Weapons!$C:$C,A8) -> 7
A9: Pistol | B9: Fast single shots, active reload | C9: Human | D9: 8 | E9: 3 | F9: =ROUND(D9*E9,1) -> 24 | G9: 420 | H9: 2 | I9: =COUNTIF(Weapons!$C:$C,A9) -> 7
A10: Scythe | B10: 360-degree sweep | C10: Demon | D10: 18 | E10: 1 | F10: =ROUND(D10*E10,1) -> 18 | G10: 90 | H10: 2 | I10: =COUNTIF(Weapons!$C:$C,A10) -> 5
A11: Spear | B11: Long thrust that pierces a line | C11: God | D11: 18 | E11: 1.2 | F11: =ROUND(D11*E11,1) -> 21.6 | G11: 130 | H11: 2 | I11: =COUNTIF(Weapons!$C:$C,A11) -> 8
A12: Drone | B12: Turret that follows you and fires on its own | C12: Alien | D12: 7 | E12: 2.5 | F12: =ROUND(D12*E12,1) -> 17.5 | G12: 300 | H12: 2 | I12: =COUNTIF(Weapons!$C:$C,A12) -> 4
A13: Shotgun | B13: Wide spread, knockback | C13: Human | D13: 30 | E13: 1 | F13: =ROUND(D13*E13,1) -> 30 | G13: 220 | H13: 4 | I13: =COUNTIF(Weapons!$C:$C,A13) -> 4
A14: Rifle | B14: Hold to charge a piercing shot | C14: Human | D14: 30 | E14: 0.8 | F14: =ROUND(D14*E14,1) -> 24 | G14: 600 | H14: 4 | I14: =COUNTIF(Weapons!$C:$C,A14) -> 5
A15: Claws | B15: Fast flurry | C15: Demon | D15: 7 | E15: 3.5 | F15: =ROUND(D15*E15,1) -> 24.5 | G15: 45 | H15: 4 | I15: =COUNTIF(Weapons!$C:$C,A15) -> 7
A16: Orbs | B16: Orbiting projectiles and auras | C16: God | D16: 6 | E16: 4 | F16: =ROUND(D16*E16,1) -> 24 | G16: 90 | H16: 4 | I16: =COUNTIF(Weapons!$C:$C,A16) -> 4
... A19: Chakram | B19: Thrown, ricochets, returns | C19: Any | D19: 15 | E19: 1.2 | F19: =ROUND(D19*E19,1) -> 18 | G19: 320 | H19: 4 | I19: =COUNTIF(Weapons!$C:$C,A19) -> 7
A20: Damage and attacks/s are level-1 values; energy beams count each 0.1 s tick as one hit.
A23: Rarity | B23: Damage multiplier | C23: Affixes | D23: Armour defence | E23: Armour bonus HP | F23: Store price (coins) | G23: Named weapons
A24: Common | B24: 1 | C24: 0 | D24: 3 | E24: 10 | F24: 25 | G24: =COUNTIF(Weapons!$F:$F,A24) -> 15
A25: Uncommon | B25: 1.06 | C25: 1 | D25: 4 | E25: 15 | F25: 60 | G25: =COUNTIF(Weapons!$F:$F,A25) -> 14
A26: Rare | B26: 1.12 | C26: 2 | D26: 5 | E26: 20 | F26: 150 | G26: =COUNTIF(Weapons!$F:$F,A26) -> 18
A27: Epic | B27: 1.2 | C27: 3 | D27: 6 | E27: 25 | F27: 400 | G27: =COUNTIF(Weapons!$F:$F,A27) -> 23
A28: Legendary | B28: 1.3 | C28: 3 | D28: 8 | E28: 35 | G28: =COUNTIF(Weapons!$F:$F,A28) -> 27
A29: Mythic | B29: 1.4 | C29: 4 | D29: 10 | E29: 45 | G29: =COUNTIF(Weapons!$F:$F,A29) -> 4
A30: Legendary and Mythic items are never sold, so their price cells stay empty.

Sheet Your list
A1: Your row | B1: Your item | C1: Your category | D1: Became (game items) | E1: Game IDs
A2: 1 | B2: Arc Reactor | C2: Power Core / Artifact | D2: Heartforge Core | E2: R18
A3: 2 | B3: Mark L / LXXXV Nanotech Armor | C3: Tactical Armor | D3: Quicksilver Plate | E3: A14
A4: 3 | B4: Palm Repulsors | C4: Energy Weapon | D4: Kinetic Palms | E4: W015
A5: 4 | B5: Unibeam | C5: Energy Weapon | D5: Core Lance | E5: W042
A6: 5 | B6: Micro-Missile Pods | C6: Ballistic / Explosive Weapon | D6: Swarm Pod | E6: W071
A7: 6 | B7: Laser Cutter | C7: Energy Weapon | D7: Torchline Cutter | E7: W011
A8: 7 | B8: J.A.R.V.I.S. / F.R.I.D.A.Y. HUD | C8: Tactical Gear / AI System | D8: Analyst Lens | E8: R08
A9: 8 | B9: Veronica (Hulkbuster) | C9: Orbital Support / Heavy Armor | D9: Siegeframe Plate | E9: A06
A10: 9 | B10: Mjolnir | C10: Mythic Melee Weapon | D10: Skyforge Maul | E10: W088
A11: 10 | B11: Worthiness Enchantment | C11: Mystical Enchantment | D11: Judgment Seal | E11: R23
A12: 11 | B12: Stormbreaker | C12: Mythic Melee Weapon | D12: Starsplit Axe | E12: W101
A13: 12 | B13: Bifrost Summoner | C13: Mystical Enchantment | D13: Bridge Sigil | E13: C04
... A186: 185 | B186: ACME Portable Hole & Toon Mallet | C186: Toon-Force Physics Gadgets | D186: Squash Mallet; Pocket Hole | E186: W005, C21
